Workbook
Name ABP_NOV25_DATA_range: 'ABP Nov 25 BWP'!$B$1:$FT$101
Name ABPAPR25_DATA_RANGE: 'ABP Apr 25 DG Khan and Vehari'!$B$5:$FS$203
Name Consolidated_data_range: 'HF R37-16 Consolidated Data'!$A$1:$FV$600
Name hf_core_data_range: 'HF core data'!$B$1:$FV$646

Sheet Dashboard
A1: HF Core Data | D1: ABP Nov 25 Data | G1: AABP Apr 25 Data | J1: DG KHAN | O1: interval " k " | P1: indexes
A2: Bahawalpur | B2: =COUNTIF(INDEX(hf_core_data_range, 0, 9), A2) -> 57 | D2: Bahawalpur | E2: =COUNTIF(INDEX(ABP_NOV25_DATA_range, 0, 9), D2) -> 100 | G2: Bahawalpur | H2: =COUNTIF(INDEX(ABPAPR25_DATA_RANGE, 0, 9), G2) -> 0 | J2: category | K2: HF | L2: ABP available | M2: selected from ABP Data | N2: sub total
A3: Jhang | B3: =COUNTIF(INDEX(hf_core_data_range, 0, 9), A3) -> 101 | D3: Jhang | E3: =COUNTIF(INDEX(ABP_NOV25_DATA_range, 0, 9), D3) -> 0 | G3: Jhang | H3: =COUNTIF(INDEX(ABPAPR25_DATA_RANGE, 0, 9), G3) -> 0 | J3: Public Place | K3: 55 | L3: 18 | M3: 0 | N3: =M3+K3 -> 55
A4: Sahiwal | B4: =COUNTIF(INDEX(hf_core_data_range, 0, 9), A4) -> 100 | D4: Sahiwal | E4: =COUNTIF(INDEX(ABP_NOV25_DATA_range, 0, 9), D4) -> 0 | G4: Sahiwal | H4: =COUNTIF(INDEX(ABPAPR25_DATA_RANGE, 0, 9), G4) -> 0 | J4: PSV | K4: 0 | L4: 16 | M4: 10 | N4: =M4+K4 -> 10 | O4: 1.67 | P4: 172, 174, 175, 177, 179, 180, 182, 184, 185, 187
A5: Dera Ghazi Khan | B5: =COUNTIF(INDEX(hf_core_data_range, 0, 9), A5) -> 72 | D5: Dera Ghazi Khan | E5: =COUNTIF(INDEX(ABP_NOV25_DATA_range, 0, 9), D5) -> 0 | G5: DG Khan | H5: =COUNTIF(INDEX(ABPAPR25_DATA_RANGE, 0, 9), G5) -> 50 | J5: Retail | K5: 17 | L5: 16 | M5: 16 | N5: =M5+K5 -> 33
A6: Mirpurkhas | B6: =COUNTIF(INDEX(hf_core_data_range, 0, 9), A6) -> 142 | D6: Mirpurkhas | E6: =COUNTIF(INDEX(ABP_NOV25_DATA_range, 0, 9), D6) -> 0 | G6: Mirpurkhas | H6: =COUNTIF(INDEX(ABPAPR25_DATA_RANGE, 0, 9), G6) -> 0 | J6: total | N6: =SUM(N3:N5) -> 98
A7: Mansehra | B7: =COUNTIF(INDEX(hf_core_data_range, 0, 9), A7) -> 103 | D7: Mansehra | E7: =COUNTIF(INDEX(ABP_NOV25_DATA_range, 0, 9), D7) -> 0 | G7: toba_tek_singh | H7: =COUNTIF(INDEX(ABPAPR25_DATA_RANGE, 0, 9), G7) -> 49 | J7: Vihari
A8: Vehari | B8: =COUNTIF(INDEX(hf_core_data_range, 0, 9), A8) -> 70 | D8: Vehari | E8: =COUNTIF(INDEX(ABP_NOV25_DATA_range, 0, 9), D8) -> 0 | G8: vihari | H8: =COUNTIF(INDEX(ABPAPR25_DATA_RANGE, 0, 9), G8) -> 50 | J8: category | K8: HF | L8: ABP available | M8: selected from ABP Data | N8: sub total
A9: total | B9: =SUM(B2:B8) -> 645 | D9: total | E9: =SUM(E2:E8) -> 100 | G9: total | H9: =SUM(H2:H8) -> 149 | J9: Public Place | K9: 56 | L9: 18 | M9: 0 | N9: 56
J10: PSV | K10: 0 | L10: 16 | M10: 10 | N10: 10 | O10: 1.67 | P10: 72, 74, 75, 77, 79, 80, 82, 84, 85, 87
A11: CONSOLDATED DATA SHEET | J11: Retail | K11: 15 | L11: 16 | M11: 16 | N11: =M11+K11 -> 31
A12: city | B12: Public place | C12: Public Service Vehicle (PSV) | D12: Retail outlet /Point of Sale (POS) | E12: Total | J12: total | N12: =SUM(N9:N11) -> 97
A13: Bahawalpur | B13: =COUNTIFS('HF R37-16 Consolidated Data'!$J$2:$J$590,$A13,'HF R37-16 Consolidated Data'!$S$2:$S$590,B$12) -> 57 | C13: =COUNTIFS('HF R37-16 Consolidated Data'!$J$2:$J$590,$A13,'HF R37-16 Consolidated Data'!$S$2:$S$590,C$12) -> 10 | D13: =COUNTIFS('HF R37-16 Consolidated Data'!$J$2:$J$590,$A13,'HF R37-16 Consolidated Data'!$S$2:$S$590,D$12) -> 33 | E13: =SUM(B13:D13) -> 100 | J13: BWP
A14: Jhang | B14: =COUNTIFS('HF R37-16 Consolidated Data'!$J$2:$J$590,$A14,'HF R37-16 Consolidated Data'!$S$2:$S$590,B$12) -> 56 | C14: =COUNTIFS('HF R37-16 Consolidated Data'!$J$2:$J$590,$A14,'HF R37-16 Consolidated Data'!$S$2:$S$590,C$12) -> 11 | D14: =COUNTIFS('HF R37-16 Consolidated Data'!$J$2:$J$590,$A14,'HF R37-16 Consolidated Data'!$S$2:$S$590,D$12) -> 34 | E14: =SUM(B14:D14) -> 101 | J14: category | K14: HF | L14: ABP available | M14: selected from ABP Data | N14: sub total
A15: Sahiwal | B15: =COUNTIFS('HF R37-16 Consolidated Data'!$J$2:$J$590,$A15,'HF R37-16 Consolidated Data'!$S$2:$S$590,B$12) -> 62 | C15: =COUNTIFS('HF R37-16 Consolidated Data'!$J$2:$J$590,$A15,'HF R37-16 Consolidated Data'!$S$2:$S$590,C$12) -> 10 | D15: =COUNTIFS('HF R37-16 Consolidated Data'!$J$2:$J$590,$A15,'HF R37-16 Consolidated Data'!$S$2:$S$590,D$12) -> 28 | E15: =SUM(B15:D15) -> 100 | J15: Public Place | K15: 57 | L15: 32 | M15: 0 | N15: 57
A16: DG Khan | B16: =COUNTIFS('HF R37-16 Consolidated Data'!$J$2:$J$590,$A16,'HF R37-16 Consolidated Data'!$S$2:$S$590,B$12) -> 55 | C16: =COUNTIFS('HF R37-16 Consolidated Data'!$J$2:$J$590,$A16,'HF R37-16 Consolidated Data'!$S$2:$S$590,C$12) -> 10 | D16: =COUNTIFS('HF R37-16 Consolidated Data'!$J$2:$J$590,$A16,'HF R37-16 Consolidated Data'!$S$2:$S$590,D$12) -> 33 | E16: =SUM(B16:D16) -> 98 | J16: PSV | K16: 0 | L16: 33 | M16: 10 | N16: 10 | O16: 3.56 | P16: 34, 38, 41, 45, 48, 52, 55, 59, 62, 66
A17: Mirpurkhas | B17: =COUNTIFS('HF R37-16 Consolidated Data'!$J$2:$J$720,$A17,'HF R37-16 Consolidated Data'!$S$2:$S$720,B$12) -> 57 | C17: =COUNTIFS('HF R37-16 Consolidated Data'!$J$2:$J$720,$A17,'HF R37-16 Consolidated Data'!$S$2:$S$720,C$12) -> 10 | D17: =COUNTIFS('HF R37-16 Consolidated Data'!$J$2:$J$720,$A17,'HF R37-16 Consolidated Data'!$S$2:$S$720,D$12) -> 33 | E17: =SUM(B17:D17) -> 100 | F17: 1.75 | G17: 277, 279, 281, 282, 284, 286, 288, 289, 291, 293, 295, 296, 298, 300, 302, 303, 305, 307, 309, 310, 312, 314, 316, 317, 319, 321, 323, 324, 326, 328, 330, 331, 333, 335, 337, 338, 340,342, 344,345, 347, 349, 351, 352, 354, 356, 358, 359, 361, 363, 365, 366, 368, 370, 372, 373,375 | J17: Retail | K17: 0 | L17: 35 | M17: 33 | N17: 33 | O17: 1.06
A18: Mansehra | B18: =COUNTIFS('HF R37-16 Consolidated Data'!$J$2:$J$590,$A18,'HF R37-16 Consolidated Data'!$S$2:$S$590,B$12) -> 59 | C18: =COUNTIFS('HF R37-16 Consolidated Data'!$J$2:$J$590,$A18,'HF R37-16 Consolidated Data'!$S$2:$S$590,C$12) -> 10 | D18: =COUNTIFS('HF R37-16 Consolidated Data'!$J$2:$J$590,$A18,'HF R37-16 Consolidated Data'!$S$2:$S$590,D$12) -> 34 | E18: =SUM(B18:D18) -> 103 | J18: total | N18: =SUM(N15:N17) -> 100
A19: Vihari | B19: =COUNTIFS('HF R37-16 Consolidated Data'!$J$2:$J$590,$A19,'HF R37-16 Consolidated Data'!$S$2:$S$590,B$12) -> 56 | C19: =COUNTIFS('HF R37-16 Consolidated Data'!$J$2:$J$600,$A19,'HF R37-16 Consolidated Data'!$S$2:$S$600,C$12) -> 10 | D19: =COUNTIFS('HF R37-16 Consolidated Data'!$J$2:$J$720,$A19,'HF R37-16 Consolidated Data'!$S$2:$S$720,D$12) -> 31 | E19: =SUM(B19:D19) -> 97
A20: TOTAL | B20: =SUM(B13:B19) -> 402 | C20: =SUM(C13:C19) -> 71 | D20: =SUM(D13:D19) -> 226 | E20: =SUM(B20:D20) -> 699

Sheet HF R37-16 Consolidated Data
A1: Row Addition Mode | B1: start | C1: end | D1: Form Number | E1: Date of Visit | F1: Start Time | G1: End time | H1: Enumerator | I1: Division | J1: District | K1: city/ Tehsil | L1: Geo Location | M1: _Geo Location _latitude | N1: _Geo Location _longitude | O1: _Geo Location _altitude | P1: _Geo Location _precision | Q1: Urban/ Rural? | R1: Name of Place | S1: Category of Place | T1: OLD A1:Type of public place | U1: Mapping status:Is the venue a Listed Venue or an unlisted venue? | V1: Mapping status:Is the venue a Listed Venue or an unlisted venue?/Listed Venue | W1: Mapping status:Is the venue a Listed Venue or an unlisted venue?/Unlisted Venue | X1: A2: Name of Public place | Y1: A3: “No Smoking Area”, “Smoking is illegal here” or similar boards are visible? | Z1: If yes, add photo Evidence | AA1: If yes, add photo Evidence _URL | AB1: If yes how many | AC1: A4: PEOPLE found smoking in the indoor area at the time of visit? | AD1: If yes, how many? | AE1: A5: STAFF found smoking in the indoor area at the time of visit? | AF1: If yes, how many? | AG1: A6: STAFF is aware of ban on smoking in public place? | AH1: A7: Authorized officer of the public place is aware of legal responsibility to stop persons from smoking indoors? | AI1: A8: Authorized officer of the public place is aware of legal responsibility to display ‘no smoking’ signboard? | AJ1: A9: If any persons were found USING any type of tobacco or nicotine product, what type are they using? | AK1: A9: If any persons were found USING any type of tobacco or nicotine product, what type are they using?/Cigarette | AL1: A9: If any persons were found USING any type of tobacco or nicotine product, what type are they using?/Naswar | AM1: A9: If any persons were found USING any type of tobacco or nicotine product, what type are they using?/Shisha / Hookah | AN1: A9: If any persons were found USING any type of tobacco or nicotine product, what type are they using?/Nicotine pouch | AO1: A9: If any persons were found USING any type of tobacco or nicotine product, what type are they using?/Heated Tobacco Products (HTPs) | AP1: A9: If any persons were found USING any type of tobacco or nicotine product, what type are they using?/E- cigarettes / vapes | AQ1: A9: If any persons were found USING any type of tobacco or nicotine product, what type are they using?/Does not apply / no one using tobacco or nicotine products | AR1: A9: If any persons were found USING any type of tobacco or nicotine product, what type are they using?/other | AS1: specify "other" | AT1: A10: If any persons were USING any type of tobacco or nicotine product, did authorized officer or staff member of the public place try to stop them? | AU1: A11: Cigarette butts are visible in the indoor area? | AV1: IIf Yes, add photo Evidence | AW1: IIf Yes, add photo Evidence _URL | AX1: A12: Ashtrays or matches are visible in the indoor area? | AY1: add photo Evidence | AZ1: add photo Evidence _URL | BA1: A13: Is there a “designated smoking area” in the public place? | BB1: add photo Evidence | BC1: add photo Evidence _URL | BD1: A14: Are there any tobacco or nicotine products being SOLD on the premises? | BE1: add photo Evidence | BF1: add photo Evidence _URL | BG1: A15: If tobacco or nicotine products are being SOLD on the premises, which products are being sold? | BH1: A15: If tobacco or nicotine products are being SOLD on the premises, which products are being sold?/Cigarette | BI1: A15: If tobacco or nicotine products are being SOLD on the premises, which products are being sold?/Naswar | BJ1: A15: If tobacco or nicotine products are being SOLD on the premises, which products are being sold?/Shisha / Hookah | BK1: A15: If tobacco or nicotine products are being SOLD on the premises, which products are being sold?/Nicotine pouch | BL1: A15: If tobacco or nicotine products are being SOLD on the premises, which products are being sold?/Heated Tobacco Products (HTPs) | BM1: A15: If tobacco or nicotine products are being SOLD on the premises, which products are being sold?/E- cigarettes / vapes | BN1: A15: If tobacco or nicotine products are being SOLD on the premises, which products are being sold?/Does not apply / no one using tobacco or nicotine products | BO1: A15: If tobacco or nicotine products are being SOLD on the premises, which products are being sold?/other | BP1: specify "other" | BQ1: A16: If tobacco products are being SOLD on the premises, does the seller have a license under TVA? | BR1: add photo Evidence | BS1: add photo Evidence _URL | BT1: A17: Were you able to complete the observation? | BU1: A18: Reason for incompletion. | BV1: A19: Additional comments (if any) | BW1: B1: Type of public service vehicle | BX1: specify "other" | BY1: B2: Name of PSV or PSV company (if applicable) | BZ1: B3: Route number or name of PSV company (if applicable) | CA1: B4: “No Smoking” sign displayed inside PSV? | CB1: B5: Driver found smoking in public vehicle? | CC1: B6: Conductor found smoking inside PSV? | CD1: B7: Passenger found smoking inside PSV? | CE1: if yes, how many? | CF1: B8: If any persons were found using Tobacco Products, what type of tobacco or nicotine product were they using? | CG1: B8: If any persons were found using Tobacco Products, what type of tobacco or nicotine product were they using?/Cigarette | CH1: B8: If any persons were found using Tobacco Products, what type of tobacco or nicotine product were they using?/Naswar | CI1: B8: If any persons were found using Tobacco Products, what type of tobacco or nicotine product were they using?/Shisha / Hookah | CJ1: B8: If any persons were found using Tobacco Products, what type of tobacco or nicotine product were they using?/Nicotine pouch | CK1: B8: If any persons were found using Tobacco Products, what type of tobacco or nicotine product were they using?/Heated Tobacco Products (HTPs) | CL1: B8: If any persons were found using Tobacco Products, what type of tobacco or nicotine product were they using?/E- cigarettes / vapes | CM1: B8: If any persons were found using Tobacco Products, what type of tobacco or nicotine product were they using?/Does not apply / no one using tobacco or nicotine products | CN1: B8: If any persons were found using Tobacco Products, what type of tobacco or nicotine product were they using?/other | CO1: specify "other" | CP1: B9: If any persons were smoking, did driver/conductor try to stop them? | CQ1: B10: Cigarette butts are visible inside the PSV? | CR1: IIf Yes, add photo Evidence | CS1: IIf Yes, add photo Evidence _URL | CT1: B11: Ashtrays are visible inside the PSV? | CU1: If Yes, add photo Evidence | CV1: If Yes, add photo Evidence _URL | CW1: B12: PSV staff is aware of ban on smoking in PSVs? | CX1: B13: PSV staff is aware of legal responsibility to display ‘no smoking’ signboard? | CY1: B14: PSV staff is aware of legal responsibility to stop persons from smoking in the vehicle? | CZ1: B15: were you able to complete the observation? | DA1: B16: Reason for incompletion. | DB1: B17: Additional comments (if any). | DC1: C1: Type of outlet | DD1: specify "other" | DE1: C2: Name of outlet | DF1: C3: Market / neighborhood of outlet | DG1: C4: Sales of tobacco products to minors (under 18 years of age) taking place at time of visit? | DH1: C5: Was the vendor checking ID cards of YOUNG buyers of tobacco products during purchase at time of visit? | DI1: C6: Is there a ‘No Sales to Minors/Persons Under 18’ sign (or similar ) on display? | DJ1: If Yes, add photo Evidence | DK1: If Yes, add photo Evidence _URL | DL1: C7: Cigarette packs without graphic health warning available for sale? | DM1: if Yes, specify brands | DN1: add photo Evidence | DO1: add photo Evidence _URL | DP1: C8: Cigarette packs without excise stamps available for sale? | DQ1: if Yes, specify brands | DR1: add photo Evidence | DS1: add photo Evidence _URL | DT1: C9: Does the seller have a license under TVA? | DU1: add photo Evidence | DV1: add photo Evidence _URL | DW1: C10: Loose cigarettes are available for sale? | DX1: C11: Cigarettes are placed next to candies, snacks or children’s products? | DY1: add photo Evidence | DZ1: add photo Evidence _URL | EA1: C12-Cig-indoor-advert: Are Cigarette brands advertized indoors? | EB1: C12-Cig-indoor-advert-brands: If yes, which brands? | EC1: C12-Cig-indoor-advert-evidence: add photo Evidence of INDOOR advertisements | ED1: C12-Cig-indoor-advert-evidence: add photo Evidence of INDOOR advertisements_URL | EE1: C12-Cig-Outdoor-advert: Are Cigarette brands advertized Outdoors? | EF1: C12-Cig-Outdoor-advert-brands: If yes, which brands? | EG1: C12-Cig-outdoor-advert-evidence: add photo Evidence of OUTDOOR advertisements | EH1: C12-Cig-outdoor-advert-evidence: add photo Evidence of OUTDOOR advertisements_URL | EI1: C12-ONP-indoor-advert: Are Nicotine Pouches advertized indoors? | EJ1: C12-ONP-indoor-advert-brands: If yes, which brands? | EK1: C12-ONP-indoor-advert-evidence: add photo Evidence of INDOOR advertisements | EL1: C12-ONP-indoor-advert-evidence: add photo Evidence of INDOOR advertisements_URL | EM1: C12-ONP-Outdoor-advert: Are Nicotine Pouches advertized outdoors? | EN1: C12-ONP-Outdoor-advert-brands: If yes, which brands? | EO1: C12-ONP-outdoor-advert-evidence: add photo Evidence of OUTDOOR advertisements | EP1: C12-ONP-outdoor-advert-evidence: add photo Evidence of OUTDOOR advertisements_URL | EQ1: C12-Other-tobacco-indoor-advert: Are "any other Tobacco Products" advertized indoors? | ER1: C12-Other-tobacco-indoor-advert-brands:If yes, which brands? | ES1: C12-Other-tobacco-advert-evidence: add photo Evidence of INDOOR advertisements | ET1: C12-Other-tobacco-advert-evidence: add photo Evidence of INDOOR advertisements_URL | EU1: C12-Other-tobacco-Outdoor-advert: Are "any other Tobacco Products" advertized outdoors? | EV1: C12-Other-tobacco-Outdoor-advert-brands: If yes, which brands? | EW1: C12-Other-tobacco-advert-evidence: add photo Evidence of OUTDOOR advertisements | EX1: C12-Other-tobacco-advert-evidence: add photo Evidence of OUTDOOR advertisements_URL | EY1: C13: Special promotions or discounts offered on purchase of tobacco products | EZ1: If Yes, add photo Evidence | FA1: If Yes, add photo Evidence _URL | FB1: If Yes, provide details | FC1: C14: Any giveaways/gifts associated with tobacco products | FD1: add photo Evidence | FE1: add photo Evidence _URL | FF1: If Yes, provide details | FG1: C15: Is the store located within 50m of an educational institution | FH1: C16: Were you able to complete the observation? | FI1: C17: Reason for incompletion. | FJ1: C18: Additional comments (if any) | FK1: City/Tehsil | FL1: _id | FM1: _uuid | FN1: _submission_time | FO1: _validation_status | FP1: _notes | FQ1: _status | FR1: _submitted_by | FS1: __version__ | FT1: _tags | FU1: meta/rootUuid | FV1: _index
A2: HF core data | B2: 46131.631 | C2: 46131.636 | D2: Sahiwal 001 | E2: 46131 | F2: 15:08:00.000+05:00 | G2: 15:20:00.000+05:00 | H2: Ashfaq Ahmed Rao | I2: Sahiwal Division | J2: Sahiwal | K2: Sahiwal | L2: 30.712628 73.055794 123 82.5 | M2: 30.712628 | N2: 73.055794 | O2: 123 | P2: 82.5 | Q2: Urban | R2: On Board Daewoo Bus | S2: Public Service Vehicle (PSV) | BW2: other | BX2: Daewoo bus sahiwal to faisalabad | BY2: Daewoo bus | BZ2: Sahiwal to faisalabad | CA2: No | CB2: No | CC2: No | CD2: No | CF2: Does not apply / no one using tobacco or nicotine products | CG2: 0 | CH2: 0 | CI2: 0 | CJ2: 0 | CK2: 0 | CL2: 0 | CM2: 1 | CN2: 0 | CP2: Does not apply / no one smoking | CQ2: No | CT2: No | CW2: No | CX2: No | CY2: Yes | CZ2: Yes | DB2: Daewoo is a well disciplined company but conductor was quite unaware of TC laws. | FL2: 729311753 | FM2: ed50e636-4f87-4e82-a888-13da994b8282 | FN2: 46131.427 | FQ2: submitted_via_web | FS2: vjiNwcPYvtjoD8cL5yiJdz | FU2: uuid:ed50e636-4f87-4e82-a888-13da994b8282 | FV2: 1
A3: HF core data | B3: 46131.636 | C3: 46131.649 | D3: Sahiwal 002 | E3: 46131 | F3: 15:22:00.000+05:00 | G3: 15:35:00.000+05:00 | H3: Ashfaq Ahmed Rao | I3: Sahiwal Division | J3: Sahiwal | K3: Sahiwal | L3: 30.647913 73.095845 131.00001525878906 31.024999618530273 | M3: 30.647913 | N3: 73.095845 | O3: 131.00002 | P3: 31.025 | Q3: Urban | R3: Daewoo Bus terminal | S3: Public place | T3: Transport Terminal (Bus terminal) | U3: Listed Venue | V3: 1 | W3: 0 | X3: Daewoo Bus terminal | Y3: Yes( add photo evidence) | Z3: 20260419_152705-15_27_30.jpg | AA3: https://kf.kobotoolbox.org/api/v2/assets/a7B4UGoSq7bg72YxNv837d/data/729322035/attachments/attggMx9uX6AD9pUkDESpzZm/ | AB3: 2 | AC3: No | AE3: No | AG3: Yes | AH3: Yes | AI3: No | AJ3: Does not apply / no one using tobacco or nicotine products | AK3: 0 | AL3: 0 | AM3: 0 | AN3: 0 | AO3: 0 | AP3: 0 | AQ3: 1 | AR3: 0 | AT3: Does not apply / no one using tobacco or nicotine products | AU3: No | AX3: No | BA3: No | BD3: No | BT3: Yes | BV3: Daewoo is a well established terminal. | FL3: 729322035 | FM3: 235bab69-dd8f-4594-9f19-e661437d2179 | FN3: 46131.441 | FQ3: submitted_via_web | FS3: vjiNwcPYvtjoD8cL5yiJdz | FU3: uuid:235bab69-dd8f-4594-9f19-e661437d2179 | FV3: 2
A4: HF core data | B4: 46131.649 | C4: 46131.657 | D4: Sahiwal 003 | E4: 46131 | F4: 15:39:00.000+05:00 | G4: 15:50:00.000+05:00 | H4: Ashfaq Ahmed Rao | I4: Sahiwal Division | J4: Sahiwal | K4: Sahiwal | L4: 30.649059 73.099694 130.60000610351562 14.022000312805176 | M4: 30.649059 | N4: 73.099694 | O4: 130.60001 | P4: 14.022 | Q4: Urban | R4: Faisal Movers Bus terminal | S4: Public place | T4: Transport Terminal (Bus terminal) | U4: Listed Venue | V4: 1 | W4: 0 | X4: Faisal Movers | Y4: No | AC4: No | AE4: Yes | AF4: 3 | AG4: Yes | AH4: Yes | AI4: No | AJ4: Cigarette | AK4: 1 | AL4: 0 | AM4: 0 | AN4: 0 | AO4: 0 | AP4: 0 | AQ4: 0 | AR4: 0 | AT4: Yes | AU4: No | AX4: No | BA4: No | BD4: No | BT4: Yes | FL4: 729329290 | FM4: c1438d41-bd27-4ca3-8d49-cdb03c35bbad | FN4: 46131.449 | FQ4: submitted_via_web | FS4: vjiNwcPYvtjoD8cL5yiJdz | FU4: uuid:c1438d41-bd27-4ca3-8d49-cdb03c35bbad | FV4: 3
A5: HF core data | B5: 46131.657 | C5: 46131.805 | D5: Sahiwal 004 | E5: 46131 | F5: 19:10:00.000+05:00 | G5: 19:25:00.000+05:00 | H5: Ashfaq Ahmed Rao | I5: Sahiwal Division | J5: Sahiwal | K5: Sahiwal | L5: 30.673535 73.108809 134.20001220703125 15.222999572753906 | M5: 30.673535 | N5: 73.108809 | O5: 134.20001 | P5: 15.223 | Q5: Urban | R5: Nomnosh Restaurant | S5: Public place | T5: Eatery ( Restaurant) | U5: Listed Venue | V5: 1 | W5: 0 | X5: Nomnosh Restaurant | Y5: Yes( add photo evidence) | Z5: 20260419_191524-19_15_37.jpg | AA5: https://kf.kobotoolbox.org/api/v2/assets/a7B4UGoSq7bg72YxNv837d/data/729448613/attachments/attekpyUWxQ3Zo7pEFaYiD58/ | AB5: 1 | AC5: No | AE5: No | AG5: Yes | AH5: Yes | AI5: Yes | AJ5: Does not apply / no one using tobacco or nicotine products | AK5: 0 | AL5: 0 | AM5: 0 | AN5: 0 | AO5: 0 | AP5: 0 | AQ5: 1 | AR5: 0 | AT5: Does not apply / no one using tobacco or nicotine products | AU5: No | AX5: No | BA5: No | BD5: No | BT5: Yes | BV5: No one allows to smoke or vape within premises. | FL5: 729448613 | FM5: 987191d7-ddc4-451f-85ae-44975b221227 | FN5: 46131.597 | FQ5: submitted_via_web | FS5: vjiNwcPYvtjoD8cL5yiJdz | FU5: uuid:987191d7-ddc4-451f-85ae-44975b221227 | FV5: 4
A6: HF core data | B6: 46131.805 | C6: 46131.815 | D6: Sahiwal 005 | E6: 46131 | F6: 19:29:00.000+05:00 | G6: 19:40:00.000+05:00 | H6: Ashfaq Ahmed Rao | I6: Sahiwal Division | J6: Sahiwal | K6: Sahiwal | L6: 30.673768 73.107722 129.8000030517578 12.095000267028809 | M6: 30.673768 | N6: 73.107722 | O6: 129.8 | P6: 12.095 | Q6: Urban | R6: KR Restaurant | S6: Public place | T6: Eatery ( Restaurant) | U6: Listed Venue | V6: 1 | W6: 0 | X6: KR Restaurant | Y6: No | AC6: No | AE6: No | AG6: Yes | AH6: Yes | AI6: Yes | AJ6: Does not apply / no one using tobacco or nicotine products | AK6: 0 | AL6: 0 | AM6: 0 | AN6: 0 | AO6: 0 | AP6: 0 | AQ6: 1 | AR6: 0 | AT6: Does not apply / no one using tobacco or nicotine products | AU6: No | AX6: No | BA6: No | BD6: No | BT6: Yes | FL6: 729456370 | FM6: ef8eeff1-d76a-45b2-af4a-3d4f55c92482 | FN6: 46131.607 | FQ6: submitted_via_web | FS6: vjiNwcPYvtjoD8cL5yiJdz | FU6: uuid:ef8eeff1-d76a-45b2-af4a-3d4f55c92482 | FV6: 5
A7: HF core data | B7: 46131.815 | C7: 46131.831 | D7: Sahiwal 006 | E7: 46131 | F7: 19:50:00.000+05:00 | G7: 19:59:00.000+05:00 | H7: Ashfaq Ahmed Rao | I7: Sahiwal Division | J7: Sahiwal | K7: Sahiwal | L7: 30.671369 73.109928 130.90000915527344 92.9000015258789 | M7: 30.671369 | N7: 73.109928 | O7: 130.90001 | P7: 92.900002 | Q7: Urban | R7: 14th Street | S7: Public place | T7: Eatery ( Restaurant) | U7: Listed Venue | V7: 1 | W7: 0 | X7: 14th Street | Y7: No | AC7: No | AE7: No | AG7: Yes | AH7: Yes | AI7: Yes | AJ7: Does not apply / no one using tobacco or nicotine products | AK7: 0 | AL7: 0 | AM7: 0 | AN7: 0 | AO7: 0 | AP7: 0 | AQ7: 1 | AR7: 0 | AT7: Does not apply / no one using tobacco or nicotine products | AU7: No | AX7: No | BA7: No | BD7: No | BT7: Yes | FL7: 729469151 | FM7: 81e01791-5ddb-4b0b-954b-37bfbc7eaa2c | FN7: 46131.623 | FQ7: submitted_via_web | FS7: vjiNwcPYvtjoD8cL5yiJdz | FU7: uuid:81e01791-5ddb-4b0b-954b-37bfbc7eaa2c | FV7: 6
A8: HF core data | B8: 46131.831 | C8: 46131.841 | D8: Sahiwal 007 | E8: 46131 | F8: 20:04:00.000+05:00 | G8: 20:17:00.000+05:00 | H8: Ashfaq Ahmed Rao | I8: Sahiwal Division | J8: Sahiwal | K8: Sahiwal | L8: 30.669103 73.109867 131.10000610351562 16.236000061035156 | M8: 30.669103 | N8: 73.109867 | O8: 131.10001 | P8: 16.236 | Q8: Urban | R8: TenDoz Restaurant | S8: Public place | T8: Eatery ( Restaurant) | U8: Listed Venue | V8: 1 | W8: 0 | X8: TenDoz | Y8: No | AC8: No | AE8: No | AG8: Yes | AH8: Yes | AI8: Yes | AJ8: Does not apply / no one using tobacco or nicotine products | AK8: 0 | AL8: 0 | AM8: 0 | AN8: 0 | AO8: 0 | AP8: 0 | AQ8: 1 | AR8: 0 | AT8: Does not apply / no one using tobacco or nicotine products | AU8: No | AX8: No | BA8: No | BD8: No | BT8: Yes | BV8: Staff was totally aware and knowledgeable regarding above questions. | FL8: 729477083 | FM8: e9253ee9-20ef-47e3-9927-b9b7c8b31851 | FN8: 46131.633 | FQ8: submitted_via_web | FS8: vjiNwcPYvtjoD8cL5yiJdz | FU8: uuid:e9253ee9-20ef-47e3-9927-b9b7c8b31851 | FV8: 7
A9: HF core data | B9: 46131.841 | C9: 46131.854 | D9: Sahiwal 008 | E9: 46131 | F9: 20:22:00.000+05:00 | G9: 20:35:00.000+05:00 | H9: Ashfaq Ahmed Rao | I9: Sahiwal Division | J9: Sahiwal | K9: Sahiwal | L9: 30.67211 73.113588 130.50001525878906 20 | M9: 30.67211 | N9: 73.113588 | O9: 130.50002 | P9: 20 | Q9: Urban | R9: The Oven Piza | S9: Public place | T9: Eatery ( Restaurant) | U9: Listed Venue | V9: 1 | W9: 0 | X9: The Oven Pizza | Y9: Yes( add photo evidence) | Z9: 20260419_202714-20_27_51.jpg | AA9: https://kf.kobotoolbox.org/api/v2/assets/a7B4UGoSq7bg72YxNv837d/data/729486742/attachments/attQmWurb2xnk5vQYUXcBZP8/ | AB9: 1 | AC9: No | AE9: No | AG9: Yes | AH9: Yes | AI9: Yes | AJ9: Does not apply / no one using tobacco or nicotine products | AK9: 0 | AL9: 0 | AM9: 0 | AN9: 0 | AO9: 0 | AP9: 0 | AQ9: 1 | AR9: 0 | AT9: Does not apply / no one using tobacco or nicotine products | AU9: No | AX9: No | BA9: No | BD9: No | BT9: Yes | FL9: 729486742 | FM9: 32a5cd2c-460b-47a4-931b-210d71ad0b2d | FN9: 46131.645 | FQ9: submitted_via_web | FS9: vjiNwcPYvtjoD8cL5yiJdz | FU9: uuid:32a5cd2c-460b-47a4-931b-210d71ad0b2d | FV9: 8
A10: HF core data | B10: 46131.854 | C10: 46131.862 | D10: Sahiwal 009 | E10: 46131 | F10: 20:35:00.000+05:00 | G10: 20:48:00.000+05:00 | H10: Ashfaq Ahmed Rao | I10: Sahiwal Division | J10: Sahiwal | K10: Sahiwal | L10: 30.669333 73.112147 131.70001220703125 11.572999954223633 | M10: 30.669333 | N10: 73.112147 | O10: 131.70001 | P10: 11.573 | Q10: Urban | R10: Cheezious | S10: Public place | T10: Eatery ( Restaurant) | U10: Listed Venue | V10: 1 | W10: 0 | X10: Cheezious Restaurant | Y10: Yes( add photo evidence) | Z10: 20260419_203831-20_39_4.jpg | AA10: https://kf.kobotoolbox.org/api/v2/assets/a7B4UGoSq7bg72YxNv837d/data/729493008/attachments/attTaqdJGpRepv7S32meV9Xh/ | AB10: 1 | AC10: No | AE10: No | AG10: Yes | AH10: Yes | AI10: Yes | AJ10: Does not apply / no one using tobacco or nicotine products | AK10: 0 | AL10: 0 | AM10: 0 | AN10: 0 | AO10: 0 | AP10: 0 | AQ10: 1 | AR10: 0 | AT10: Does not apply / no one using tobacco or nicotine products | AU10: No | AX10: No | BA10: No | BD10: No | BT10: Yes | FL10: 729493008 | FM10: 6993718c-e9eb-4af4-88f9-a32b38db888a | FN10: 46131.653 | FQ10: submitted_via_web | FS10: vjiNwcPYvtjoD8cL5yiJdz | FU10: uuid:6993718c-e9eb-4af4-88f9-a32b38db888a | FV10: 9
A11: HF core data | B11: 46131.862 | C11: 46131.905 | D11: Sahiwal 10 | E11: 46131 | F11: 21:38:00.000+05:00 | G11: 21:55:00.000+05:00 | H11: Ashfaq Ahmed Rao | I11: Sahiwal Division | J11: Sahiwal | K11: Sahiwal | L11: 30.678097 73.0888 127.4000015258789 18.014999389648438 | M11: 30.678097 | N11: 73.0888 | O11: 127.4 | P11: 18.014999 | Q11: Urban | R11: Spice Villa | S11: Public place | T11: Eatery ( Restaurant) | U11: Listed Venue | V11: 1 | W11: 0 | X11: Spice Villa | Y11: Yes( add photo evidence) | Z11: 20260419_214050-21_41_0.jpg | AA11: https://kf.kobotoolbox.org/api/v2/assets/a7B4UGoSq7bg72YxNv837d/data/729526431/attachments/attHDaZGttmRVxddMD2Ba7Mo/ | AB11: 1 | AC11: No | AE11: No | AG11: No | AH11: Yes | AI11: Yes | AJ11: Does not apply / no one using tobacco or nicotine products | AK11: 0 | AL11: 0 | AM11: 0 | AN11: 0 | AO11: 0 | AP11: 0 | AQ11: 1 | AR11: 0 | AT11: Does not apply / no one using tobacco or nicotine products | AU11: No | AX11: No | BA11: No | BD11: No | BT11: Yes | FL11: 729526431 | FM11: 7c9eb1ed-dcab-401e-836b-d7c958e26c98 | FN11: 46131.697 | FQ11: submitted_via_web | FS11: vjiNwcPYvtjoD8cL5yiJdz | FU11: uuid:7c9eb1ed-dcab-401e-836b-d7c958e26c98 | FV11: 10
A12: HF core data | B12: 46128.619 | C12: 46132.341 | D12: Jhang0079 | E12: 46128 | F12: 15:13:00.000+05:00 | G12: 15:28:00.000+05:00 | H12: Tahir Mustafa | I12: Faisalabad Division | J12: Jhang | K12: Jhang | L12: 31.260871 72.352786 115.5999984741211 21.773000717163086 | M12: 31.260871 | N12: 72.352786 | O12: 115.6 | P12: 21.773001 | Q12: Urban | R12: Town guest house | S12: Public place | T12: Accommodation - Guesthouse | U12: Listed Venue | V12: 1 | W12: 0 | X12: Town guest house | Y12: No | AC12: No | AE12: No | AG12: Yes | AH12: Yes | AI12: Yes | AJ12: Does not apply / no one using tobacco or nicotine products | AK12: 0 | AL12: 0 | AM12: 0 | AN12: 0 | AO12: 0 | AP12: 0 | AQ12: 1 | AR12: 0 | AT12: Does not apply / no one using tobacco or nicotine products | AU12: No | AX12: No | BA12: No | BD12: No | BT12: Yes | BV12: Al Madina guest house map ma town guest tha TU liya ma na town guest Kya ha | FL12: 729957908 | FM12: c8f2d82c-001c-4dd6-93da-d2a8f57ad3a4 | FN12: 46132.328 | FQ12: submitted_via_web | FS12: vjiNwcPYvtjoD8cL5yiJdz | FU12: uuid:c8f2d82c-001c-4dd6-93da-d2a8f57ad3a4 | FV12: 11
A13: HF core data | B13: 46127.43 | C13: 46132.536 | D13: 0051 | E13: 46127 | F13: 11:20:00.000+05:00 | G13: 11:35:00.000+05:00 | H13: Tahir Mustafa | I13: Faisalabad Division | J13: Jhang | K13: Jhang | L13: 31.262447 72.330422 112.69999694824219 13.836000442504883 | M13: 31.262447 | N13: 72.330422 | O13: 112.7 | P13: 13.836 | Q13: Urban | R13: Chief Executive Office District Health Authority Jhang - Gojra Rd, Jhan | S13: Public place | T13: Government Offices - District Authorities Offices e.g. (Health, Education, DC Office, C & W Office, Social Welfare etc.) | U13: Listed Venue | V13: 1 | W13: 0 | X13: Chief Executive Office District Health Authority Jhang - Gojra Rd, Jhan | Y13: No | AC13: No | AE13: No | AG13: Yes | AH13: Yes | AI13: Yes | AJ13: Does not apply / no one using tobacco or nicotine products | AK13: 0 | AL13: 0 | AM13: 0 | AN13: 0 | AO13: 0 | AP13: 0 | AQ13: 1 | AR13: 0 | AT13: No | AU13: Yes ( add photo Evidence) | AV13: 1000074957-11_33_11.jpg | AW13: https://kf.kobotoolbox.org/api/v2/assets/a7B4UGoSq7bg72YxNv837d/data/729957928/attachments/attQqiFcFBKHZNXSE56A7oCR/ | AX13: Yes (add photo Evidence) | AY13: 1000074956-11_31_27.jpg | AZ13: https://kf.kobotoolbox.org/api/v2/assets/a7B4UGoSq7bg72YxNv837d/data/729957928/attachments/attErBzjuf28RHZRnZuFFuZK/ | BA13: No | BD13: No | BT13: Yes | BV13: Cooperative staff | FL13: 729957928 | FM13: 6081b523-71ce-42c4-b0af-2da5a35a61fc | FN13: 46132.328 | FQ13: submitted_via_web | FS13: vjiNwcPYvtjoD8cL5yiJdz | FU13: uuid:6081b523-71ce-42c4-b0af-2da5a35a61fc | FV13: 12
A14: HF core data | B14: 46127.488 | C14: 46132.537 | D14: Jhang 0052 | E14: 46128 | F14: 11:48:00.000+05:00 | G14: 12:05:00.000+05:00 | H14: Tahir Mustafa | I14: Faisalabad Division | J14: Jhang | K14: Jhang | L14: 31.279195 72.354852 113.5999984741211 0.9459999799728394 | M14: 31.279195 | N14: 72.354852 | O14: 113.6 | P14: 0.94599998 | Q14: Urban | R14: Expire college group of jhang | S14: Public place | T14: Entertainment/sports venue - Cinema | U14: Listed Venue Unlisted Venue | V14: 1 | W14: 1 | X14: Aspir college group jhang | Y14: No | AC14: No | AE14: No | AG14: Yes | AH14: Yes | AI14: Yes | AJ14: Does not apply / no one using tobacco or nicotine products | AK14: 0 | AL14: 0 | AM14: 0 | AN14: 0 | AO14: 0 | AP14: 0 | AQ14: 1 | AR14: 0 | AT14: Does not apply / no one using tobacco or nicotine products | AU14: No | AX14: No | BA14: No | BD14: No | BT14: Yes | FL14: 729958274 | FM14: bd7acc68-5518-48e9-adfd-33467a217a76 | FN14: 46132.328 | FQ14: submitted_via_web | FS14: vjiNwcPYvtjoD8cL5yiJdz | FU14: uuid:bd7acc68-5518-48e9-adfd-33467a217a76 | FV14: 13
A15: HF core data | B15: 46127.524 | C15: 46132.537 | D15: Jhang 0053 | E15: 46127 | F15: 12:35:00.000+05:00 | G15: 12:50:00.000+05:00 | H15: Tahir Mustafa | I15: Faisalabad Division | J15: Jhang | K15: Jhang | L15: 31.279135 72.313275 115.0999984741211 32.45100021362305 | M15: 31.279135 | N15: 72.313275 | O15: 115.1 | P15: 32.451 | Q15: Urban | R15: Municipal Corporation Circular Rd, Madina Colony, Jhang | S15: Public place | T15: Government Offices - District court/ Bar council | U15: Listed Venue | V15: 1 | W15: 0 | X15: Municipal Corporation Circular Rd, Madina Colony, Jhang | Y15: No | AC15: Yes | AD15: 1 | AE15: No | AG15: Yes | AH15: No | AI15: No | AJ15: Cigarette | AK15: 1 | AL15: 0 | AM15: 0 | AN15: 0 | AO15: 0 | AP15: 0 | AQ15: 0 | AR15: 0 | AT15: No | AU15: Yes ( add photo Evidence) | AV15: 1000074964-12_41_27.jpg | AW15: https://kf.kobotoolbox.org/api/v2/assets/a7B4UGoSq7bg72YxNv837d/data/729958722/attachments/attdTwZpgLCufAc3XqPDPTPz/ | AX15: No | BA15: No | BD15: No | BT15: Yes | FL15: 729958722 | FM15: 7ae4a41e-e745-44e2-82dd-55727f6a9143 | FN15: 46132.329 | FQ15: submitted_via_web | FS15: vjiNwcPYvtjoD8cL5yiJdz | FU15: uuid:7ae4a41e-e745-44e2-82dd-55727f6a9143 | FV15: 14
A16: HF core data | B16: 46127.552 | C16: 46132.537 | D16: Jhang 0054 | E16: 46127 | F16: 13:15:00.000+05:00 | G16: 13:30:00.000+05:00 | H16: Tahir Mustafa | I16: Faisalabad Division | J16: Jhang | K16: Jhang | L16: 31.277981 72.32404 123.77 1.4390000104904175 | M16: 31.277981 | N16: 72.32404 | O16: 123.77 | P16: 1.439 | Q16: Urban | R16: Punjab Food Authority Jhang Sadar | S16: Public place | T16: Government Offices - District Authorities Offices e.g. (Health, Education, DC Office, C & W Office, Social Welfare etc.) | U16: Listed Venue | V16: 1 | W16: 0 | X16: Punjab Food Authority Jhang Sadar | Y16: Yes( add photo evidence) | Z16: 1000074971-13_16_49.jpg | AA16: https://kf.kobotoolbox.org/api/v2/assets/a7B4UGoSq7bg72YxNv837d/data/729958993/attachments/attzL2764tSCcDhaQXSXVYxo/ | AB16: 1 | AC16: No | AE16: No | AG16: Yes | AH16: Yes | AI16: Yes | AJ16: Does not apply / no one using tobacco or nicotine products | AK16: 0 | AL16: 0 | AM16: 0 | AN16: 0 | AO16: 0 | AP16: 0 | AQ16: 1 | AR16: 0 | AT16: Does not apply / no one using tobacco or nicotine products | AU16: Yes ( add photo Evidence) | AV16: 1000074972-13_20_23.jpg | AW16: https://kf.kobotoolbox.org/api/v2/assets/a7B4UGoSq7bg72YxNv837d/data/729958993/attachments/attAwsRPSSoszhV74iJ33bVk/ | AX16: No | BA16: Yes (add photo Evidence) | BB16: 1000074974-13_24_2.jpg | BC16: https://kf.kobotoolbox.org/api/v2/assets/a7B4UGoSq7bg72YxNv837d/data/729958993/attachments/attnB39MHzPAofL28DgJF6pK/ | BD16: Yes (add photo Evidence) | BE16: 1000074973-13_23_10.jpg | BF16: https://kf.kobotoolbox.org/api/v2/assets/a7B4UGoSq7bg72YxNv837d/data/729958993/attachments/attnycw62XjaY7iMniXfsDrL/ | BG16: Does not apply / no one using tobacco or nicotine products | BH16: 0 | BI16: 0 | BJ16: 0 | BK16: 0 | BL16: 0 | BM16: 0 | BN16: 1 | BO16: 0 | BQ16: TVA not enforced in the district | BT16: Yes | FL16: 729958993 | FM16: 1725fbef-afb9-4b4f-b2a1-e333496e7f33 | FN16: 46132.329 | FQ16: submitted_via_web | FS16: vjiNwcPYvtjoD8cL5yiJdz | FU16: uuid:1725fbef-afb9-4b4f-b2a1-e333496e7f33 | FV16: 15
A17: HF core data | B17: 46127.578 | C17: 46132.537 | D17: Jhang 0055 | E17: 46127 | F17: 13:52:00.000+05:00 | G17: 14:08:00.000+05:00 | H17: Tahir Mustafa | I17: Faisalabad Division | J17: Jhang | K17: Jhang | L17: 31.27184 72.318195 115 16.93600082397461 | M17: 31.27184 | N17: 72.318195 | O17: 115 | P17: 16.936001 | Q17: Urban | R17: Habib Bank Limited (HBL) Shaheed Rd, | S17: Public place | T17: Bank - private | U17: Listed Venue | V17: 1 | W17: 0 | X17: Habib Bank Limited (HBL) Shaheed Rd, | Y17: No | AC17: No | AE17: No | AG17: Yes | AH17: Yes | AI17: No | AJ17: Does not apply / no one using tobacco or nicotine products | AK17: 0 | AL17: 0 | AM17: 0 | AN17: 0 | AO17: 0 | AP17: 0 | AQ17: 1 | AR17: 0 | AT17: No | AU17: No | AX17: No | BA17: No | BD17: No | BT17: Yes | FL17: 729959159 | FM17: efadde04-c949-4814-8daa-d8f1c10ee3da | FN17: 46132.329 | FQ17: submitted_via_web | FS17: vjiNwcPYvtjoD8cL5yiJdz | FU17: uuid:efadde04-c949-4814-8daa-d8f1c10ee3da | FV17: 16
A18: HF core data | B18: 46127.604 | C18: 46132.537 | D18: Jhang0056 | E18: 46127 | F18: 14:29:00.000+05:00 | G18: 14:45:00.000+05:00 | H18: Tahir Mustafa | I18: Faisalabad Division | J18: Jhang | K18: Jhang | L18: 31.268795 72.316982 115.19999694824219 12.597999572753906 | M18: 31.268795 | N18: 72.316982 | O18: 115.2 | P18: 12.598 | Q18: Urban | R18: Nighat Medical Complex Gojra Rd, near Post Office | S18: Public place | T18: Health Facility - Hospital | U18: Listed Venue | V18: 1 | W18: 0 | X18: Nighat Medical Complex Gojra Rd, near Post Office | Y18: Yes( add photo evidence) | Z18: 1000074977-14_43_44.jpg | AA18: https://kf.kobotoolbox.org/api/v2/assets/a7B4UGoSq7bg72YxNv837d/data/729959559/attachments/attAhyxwNri4LKK5kLaALrSy/ | AB18: 1 | AC18: No | AE18: No | AG18: Yes | AH18: Yes | AI18: Yes | AJ18: Does not apply / no one using tobacco or nicotine products | AK18: 0 | AL18: 0 | AM18: 0 | AN18: 0 | AO18: 0 | AP18: 0 | AQ18: 1 | AR18: 0 | AT18: Does not apply / no one using tobacco or nicotine products | AU18: No | AX18: No | BA18: No | BD18: No | BT18: Yes | FL18: 729959559 | FM18: 3ef1fc9a-01eb-4133-a224-4d3c3fe1632f | FN18: 46132.329 | FQ18: submitted_via_web | FS18: vjiNwcPYvtjoD8cL5yiJdz | FU18: uuid:3ef1fc9a-01eb-4133-a224-4d3c3fe1632f | FV18: 17
A19: HF core data | B19: 46127.624 | C19: 46132.538 | D19: Jhang 0057 | E19: 46127 | F19: 14:58:00.000+05:00 | G19: 15:12:00.000+05:00 | H19: Tahir Mustafa | I19: Faisalabad Division | J19: Jhang | K19: Jhang | L19: 31.261565 72.306956 116.58 10.428999900817871 | M19: 31.261565 | N19: 72.306956 | O19: 116.58 | P19: 10.429 | Q19: Urban | R19: Iqbal Memorial Hospital Bhakkar Rd, Jhang Sadar | S19: Public place | T19: Health Facility - Hospital | U19: Listed Venue | V19: 1 | W19: 0 | X19: Iqbal Memorial Hospital Bhakkar Rd, Jhang Sadar | Y19: Yes( add photo evidence) | Z19: 1000074982-15_3_7.jpg | AA19: https://kf.kobotoolbox.org/api/v2/assets/a7B4UGoSq7bg72YxNv837d/data/729959818/attachments/attWHi2rLujorkU4h5nMhNep/ | AB19: 1 | AC19: No | AE19: No | AG19: Yes | AH19: Yes | AI19: Yes | AJ19: Does not apply / no one using tobacco or nicotine products | AK19: 0 | AL19: 0 | AM19: 0 | AN19: 0 | AO19: 0 | AP19: 0 | AQ19: 1 | AR19: 0 | AT19: Does not apply / no one using tobacco or nicotine products | AU19: No | AX19: No | BA19: No | BD19: No | BT19: Yes | FL19: 729959818 | FM19: f41f2fd5-90f4-426d-8483-88b10a215bbf | FN19: 46132.329 | FQ19: submitted_via_web | FS19: vjiNwcPYvtjoD8cL5yiJdz | FU19: uuid:f41f2fd5-90f4-426d-8483-88b10a215bbf | FV19: 18
A20: HF core data | B20: 46127.663 | C20: 46132.538 | D20: Jhang0058 | E20: 46127 | F20: 15:55:00.000+05:00 | G20: 16:10:00.000+05:00 | H20: Tahir Mustafa | I20: Faisalabad Division | J20: Jhang | K20: Jhang | L20: 31.274381 72.316068 115.80000305175781 17.81599998474121 | M20: 31.274381 | N20: 72.316068 | O20: 115.8 | P20: 17.816 | Q20: Rural | R20: Telenor Pakistan Franchise Shaheed Rd, Jhang Private Offices 2 | S20: Public place | T20: Bank - private | U20: Listed Venue | V20: 1 | W20: 0 | X20: Telenor Pakistan Franchise Shaheed Rd, Jhang Private Offices 2 | Y20: No | AC20: No | AE20: No | AG20: Yes | AH20: Yes | AI20: Yes | AJ20: Does not apply / no one using tobacco or nicotine products | AK20: 0 | AL20: 0 | AM20: 0 | AN20: 0 | AO20: 0 | AP20: 0 | AQ20: 1 | AR20: 0 | AT20: Does not apply / no one using tobacco or nicotine products | AU20: No | AX20: No | BA20: No | BD20: No | BT20: Yes | FL20: 729960840 | FM20: e7416257-7c09-4d1d-9834-81b48e09f794 | FN20: 46132.33 | FQ20: submitted_via_web | FS20: vjiNwcPYvtjoD8cL5yiJdz | FU20: uuid:e7416257-7c09-4d1d-9834-81b48e09f794 | FV20: 19
A21: HF core data | B21: 46127.682 | C21: 46132.538 | D21: Jhang 0059 | E21: 46127 | F21: 16:21:00.000+05:00 | G21: 16:37:00.000+05:00 | H21: Tahir Mustafa | I21: Faisalabad Division | J21: Jhang | K21: Jhang | L21: 31.262903 72.335495 115.4000015258789 21.83799934387207 | M21: 31.262903 | N21: 72.335495 | O21: 115.4 | P21: 21.837999 | Q21: Urban | R21: Meet And Eat Opp DHQ Hospital Jhang Gojra Rd | S21: Public place | T21: Eatery ( Restaurant) | U21: Listed Venue | V21: 1 | W21: 0 | X21: Meet And Eat Opp DHQ Hospital Jhang Gojra Rd | Y21: No | AC21: No | AE21: No | AG21: Yes | AH21: Yes | AI21: Yes | AJ21: Does not apply / no one using tobacco or nicotine products | AK21: 0 | AL21: 0 | AM21: 0 | AN21: 0 | AO21: 0 | AP21: 0 | AQ21: 1 | AR21: 0 | AT21: Does not apply / no one using tobacco or nicotine products | AU21: No | AX21: No | BA21: No | BD21: No | BT21: Yes | FL21: 729961044 | FM21: 3f8b283a-bd5b-4871-8f87-097bc60c414d | FN21: 46132.33 | FQ21: submitted_via_web | FS21: vjiNwcPYvtjoD8cL5yiJdz | FU21: uuid:3f8b283a-bd5b-4871-8f87-097bc60c414d | FV21: 20
A22: HF core data | B22: 46127.702 | C22: 46132.538 | D22: Jhang 0060 | E22: 46127 | F22: 17:15:00.000+05:00 | G22: 17:30:00.000+05:00 | H22: Tahir Mustafa | I22: Faisalabad Division | J22: Jhang | K22: Jhang | L22: 31.268155 72.345802 78.42 1.784999966621399 | M22: 31.268155 | N22: 72.345802 | O22: 78.42 | P22: 1.785 | Q22: Urban | R22: Sakina Hospital Dar-ul-Sakina Rd, Ghaziabad, Jhang | S22: Public place | T22: Health Facility - Hospital | U22: Listed Venue | V22: 1 | W22: 0 | X22: Sakina Hospital Dar-ul-Sakina Rd, Ghaziabad, Jhang | Y22: Yes( add photo evidence) | Z22: 1000075023-17_26_41.jpg | AA22: https://kf.kobotoolbox.org/api/v2/assets/a7B4UGoSq7bg72YxNv837d/data/729961277/attachments/attr6A2SWaG37uqQmLsEzHy5/ | AB22: 1 | AC22: No | AE22: No | AG22: Yes | AH22: Yes | AI22: Yes | AJ22: Does not apply / no one using tobacco or nicotine products | AK22: 0 | AL22: 0 | AM22: 0 | AN22: 0 | AO22: 0 | AP22: 0 | AQ22: 1 | AR22: 0 | AT22: Does not apply / no one using tobacco or nicotine products | AU22: No | AX22: No | BA22: No | BD22: No | BT22: Yes | FL22: 729961277 | FM22: 28ec7e7a-907a-4cf3-ac41-88a04d877eb4 | FN22: 46132.33 | FQ22: submitted_via_web | FS22: vjiNwcPYvtjoD8cL5yiJdz | FU22: uuid:28ec7e7a-907a-4cf3-ac41-88a04d877eb4 | FV22: 21
A23: HF core data | B23: 46127.747 | C23: 46132.539 | D23: Jhang 0061 | E23: 46127 | F23: 17:56:00.000+05:00 | G23: 18:11:00.000+05:00 | H23: Tahir Mustafa | I23: Faisalabad Division | J23: Jhang | K23: Jhang | L23: 31.27016 72.317782 113.69999694824219 20 | M23: 31.27016 | N23: 72.317782 | O23: 113.7 | P23: 20 | Q23: Urban | R23: The hot spot cafe and restaurants | S23: Public place | T23: Eatery ( Restaurant) | U23: Listed Venue | V23: 1 | W23: 0 | X23: The hot spot cafe and restaurants | Y23: No | AC23: No | AE23: No | AG23: Yes | AH23: No | AI23: No | AJ23: Does not apply / no one using tobacco or nicotine products | AK23: 0 | AL23: 0 | AM23: 0 | AN23: 0 | AO23: 0 | AP23: 0 | AQ23: 1 | AR23: 0 | AT23: Does not apply / no one using tobacco or nicotine products | AU23: No | AX23: No | BA23: No | BD23: No | BT23: Yes | FL23: 729961744 | FM23: 3427bdd2-120c-4314-b5ef-1edbb59f523c | FN23: 46132.33 | FQ23: submitted_via_web | FS23: vjiNwcPYvtjoD8cL5yiJdz | FU23: uuid:3427bdd2-120c-4314-b5ef-1edbb59f523c | FV23: 22
A24: HF core data | B24: 46127.813 | C24: 46132.539 | D24: Jhang 0062 | E24: 46127 | F24: 19:35:00.000+05:00 | G24: 19:50:00.000+05:00 | H24: Tahir Mustafa | I24: Faisalabad Division | J24: Jhang | K24: Jhang | L24: 31.277684 72.321064 114.80000305175781 24.851999282836914 | M24: 31.277684 | N24: 72.321064 | O24: 114.8 | P24: 24.851999 | Q24: Urban | R24: al jannat bakery | S24: Public place | T24: Eatery ( Bakery) | U24: Unlisted Venue | V24: 0 | W24: 1 | X24: Al jannat bakery | Y24: No | AC24: No | AE24: No | AG24: No | AH24: Yes | AI24: Yes | AJ24: Does not apply / no one using tobacco or nicotine products | AK24: 0 | AL24: 0 | AM24: 0 | AN24: 0 | AO24: 0 | AP24: 0 | AQ24: 1 | AR24: 0 | AT24: Does not apply / no one using tobacco or nicotine products | AU24: Yes ( add photo Evidence) | AV24: 1000075056-19_41_16.jpg | AW24: https://kf.kobotoolbox.org/api/v2/assets/a7B4UGoSq7bg72YxNv837d/data/729962050/attachments/att58Q7qxVkogZtx7RzFbAd6/ | AX24: Yes (add photo Evidence) | AY24: 1000075057-19_41_39.jpg | AZ24: https://kf.kobotoolbox.org/api/v2/assets/a7B4UGoSq7bg72YxNv837d/data/729962050/attachments/attMmB3pb3QG4FStoGiBqa6N/ | BA24: No | BD24: No | BT24: Yes | FL24: 729962050 | FM24: 95e833c7-0812-4681-9d52-842e64f54d57 | FN24: 46132.331 | FQ24: submitted_via_web | FS24: vjiNwcPYvtjoD8cL5yiJdz | FU24: uuid:95e833c7-0812-4681-9d52-842e64f54d57 | FV24: 23
A25: HF core data | B25: 46127.823 | C25: 46132.539 | D25: Jhang0063 | E25: 46127 | F25: 19:55:00.000+05:00 | G25: 20:10:00.000+05:00 | H25: Tahir Mustafa | I25: Faisalabad Division | J25: Jhang | K25: Jhang | L25: 31.276723 72.320416 115 18.354000091552734 | M25: 31.276723 | N25: 72.320416 | O25: 115 | P25: 18.354 | Q25: Urban | R25: Pso of jhang | S25: Retail outlet /Point of Sale (POS) | DC25: Fuel station | DE25: Pso of jhang | DF25: Ayub Chowk | DG25: No | DH25: Not Applicable/ No Young buyers visited | DI25: No | DL25: No | DP25: No | DT25: No | DW25: No | DX25: No | EA25: No | EE25: Yes | EF25: Capstan | EG25: 1000075070-19_56_49.jpg | EH25: https://kf.kobotoolbox.org/api/v2/assets/a7B4UGoSq7bg72YxNv837d/data/729962878/attachments/attNuj4aWvMr8n6QrsjazZmY/ | EI25: No | EM25: No | EQ25: No | EU25: No | EY25: No | FC25: No | FG25: Yes | FH25: Yes | FL25: 729962878 | FM25: 81ecf395-5223-4a18-bdd0-9c1114322db3 | FN25: 46132.331 | FQ25: submitted_via_web | FS25: vjiNwcPYvtjoD8cL5yiJdz | FU25: uuid:81ecf395-5223-4a18-bdd0-9c1114322db3 | FV25: 24
A26: HF core data | B26: 46128.255 | C26: 46132.54 | D26: Jhang0064 | E26: 46128 | F26: 06:06:00.000+05:00 | G26: 06:18:00.000+05:00 | H26: Tahir Mustafa | I26: Faisalabad Division | J26: Jhang | K26: Jhang | L26: 31.277014 72.320864 114.80000305175781 23.39299964904785 | M26: 31.277014 | N26: 72.320864 | O26: 114.8 | P26: 23.393 | Q26: Urban | R26: Abdul Majid panwala | S26: Retail outlet /Point of Sale (POS) | DC26: Tobacco shop | DE26: Abdul Majid panwala | DF26: Ayub Chowk | DG26: No | DH26: Not Applicable/ No Young buyers visited | DI26: No | DL26: No | DP26: No | DT26: No | DW26: Yes | DX26: Yes ( add photo evidence) | DY26: 1000075119-6_10_15.jpg | DZ26: https://kf.kobotoolbox.org/api/v2/assets/a7B4UGoSq7bg72YxNv837d/data/729963344/attachments/att6P7dBLtzPnHBdMFjRCwah/ | EA26: Yes | EB26: Capstan | EC26: 1000075119-6_10_31.jpg | ED26: https://kf.kobotoolbox.org/api/v2/assets/a7B4UGoSq7bg72YxNv837d/data/729963344/attachments/attjqK9bS8LDua3GPqoqVNWH/ | EE26: Yes | EF26: Capstan | EG26: 1000075119-6_10_44.jpg | EH26: https://kf.kobotoolbox.org/api/v2/assets/a7B4UGoSq7bg72YxNv837d/data/729963344/attachments/attLk2ZUxqHycuQACbMqRxeV/ | EI26: No | EM26: No | EQ26: Yes | ER26: Zyx | ES26: 1000075120-11_36_54.jpg | ET26: https://kf.kobotoolbox.org/api/v2/assets/a7B4UGoSq7bg72YxNv837d/data/729963344/attachments/attKWpqxzNpmHRtowptQmekf/ | EU26: Yes | EV26: Zyx | EW26: 1000075120-6_11_57.jpg | EX26: https://kf.kobotoolbox.org/api/v2/assets/a7B4UGoSq7bg72YxNv837d/data/729963344/attachments/attRWZj4wxaSmijKh2Zfjsc8/ | EY26: Yes ( add photo evidence) | EZ26: 1000075121-6_12_20.jpg | FA26: https://kf.kobotoolbox.org/api/v2/assets/a7B4UGoSq7bg72YxNv837d/data/729963344/attachments/attXdGBdZp3DPcoa86NsJrud/ | FB26: World no 1 | FC26: No | FG26: Yes | FH26: Yes | FL26: 729963344 | FM26: 898b69c6-4f10-4896-8047-e74ec02fac21 | FN26: 46132.331 | FQ26: submitted_via_web | FS26: vjiNwcPYvtjoD8cL5yiJdz | FU26: uuid:898b69c6-4f10-4896-8047-e74ec02fac21 | FV26: 25
A27: HF core data | B27: 46128.261 | C27: 46132.542 | D27: Jhang0065 | E27: 46128 | F27: 06:21:00.000+05:00 | G27: 06:26:00.000+05:00 | H27: Tahir Mustafa | I27: Faisalabad Division | J27: Jhang | K27: Jhang | L27: 31.282936 72.33188 111.0999984741211 77.5999984741211 | M27: 31.282936 | N27: 72.33188 | O27: 111.1 | P27: 77.599998 | Q27: Urban | R27: Sargodha road | S27: Public Service Vehicle (PSV) | BW27: other | BX27: Raksha | BY27: Raksha | BZ27: Sargodha road | CA27: No | CB27: No | CC27: No | CD27: No | CF27: Does not apply / no one using tobacco or nicotine products | CG27: 0 | CH27: 0 | CI27: 0 | CJ27: 0 | CK27: 0 | CL27: 0 | CM27: 1 | CN27: 0 | CP27: Does not apply / no one smoking | CQ27: No | CT27: No | CW27: Yes | CX27: Yes | CY27: Yes | CZ27: Yes | FL27: 729967349 | FM27: cee959d5-d6a5-439a-b8ee-6cf07e16d329 | FN27: 46132.334 | FQ27: submitted_via_web | FS27: vjiNwcPYvtjoD8cL5yiJdz | FU27: uuid:cee959d5-d6a5-439a-b8ee-6cf07e16d329 | FV27: 26
A28: HF core data | B28: 46128.272 | C28: 46132.542 | D28: Jhang066 | E28: 46128 | F28: 06:31:00.000+05:00 | G28: 06:45:00.000+05:00 | H28: Tahir Mustafa | I28: Faisalabad Division | J28: Jhang | K28: Jhang | L28: 31.282935 72.331878 111.0999984741211 87.5999984741211 | M28: 31.282935 | N28: 72.331878 | O28: 111.1 | P28: 87.599998 | Q28: Urban | R28: Akhtar pan shop | S28: Retail outlet /Point of Sale (POS) | DC28: Tobacco shop | DE28: Akhtar pan shop | DF28: Sargodha road | DG28: No | DH28: Not Applicable/ No Young buyers visited | DI28: No | DL28: No | DP28: No | DT28: No | DW28: Yes | DX28: Yes ( add photo evidence) | DY28: 1000075123-6_36_5.jpg | DZ28: https://kf.kobotoolbox.org/api/v2/assets/a7B4UGoSq7bg72YxNv837d/data/729967485/attachments/attiRf2LaEN5ABPLtRswB3X9/ | EA28: Yes | EB28: Capstan | EC28: 1000075123-6_36_18.jpg | ED28: https://kf.kobotoolbox.org/api/v2/assets/a7B4UGoSq7bg72YxNv837d/data/729967485/attachments/attyszacAmb5PooL4Qc6QiK4/ | EE28: No | EI28: No | EM28: No | EQ28: No | EU28: No | EY28: Yes ( add photo evidence) | EZ28: 1000075124-6_36_57.jpg | FA28: https://kf.kobotoolbox.org/api/v2/assets/a7B4UGoSq7bg72YxNv837d/data/729967485/attachments/attPUAArxai2hBjMheznqAUP/ | FB28: Capstan 172 sale | FC28: No | FG28: Yes | FH28: Yes | FL28: 729967485 | FM28: 669206a7-6433-405f-89c5-37172d6fb27e | FN28: 46132.334 | FQ28: submitted_via_web | FS28: vjiNwcPYvtjoD8cL5yiJdz | FU28: uuid:669206a7-6433-405f-89c5-37172d6fb27e | FV28: 27
A29: HF core data | B29: 46128.292 | C29: 46132.542 | D29: Jhang0067 | E29: 46128 | F29: 07:00:00.000+05:00 | G29: 07:11:00.000+05:00 | H29: Tahir Mustafa | I29: Faisalabad Division | J29: Jhang | K29: Jhang | L29: 31.273754 72.319133 114.19999694824219 5.494999885559082 | M29: 31.273754 | N29: 72.319133 | O29: 114.2 | P29: 5.4949999 | Q29: Urban | R29: Shell v power petrol | S29: Retail outlet /Point of Sale (POS) | DC29: Fuel station | DE29: Shell v power | DF29: Car wash | DG29: No | DH29: Not Applicable/ No Young buyers visited | DI29: No | DL29: No | DP29: No | DT29: No | DW29: No | DX29: No | EA29: No | EE29: No | EI29: No | EM29: No | EQ29: No | EU29: No | EY29: No | FC29: No | FG29: No | FH29: Yes | FL29: 729967601 | FM29: cc7e7013-7357-40e8-a6d6-9ad41bbbb465 | FN29: 46132.334 | FQ29: submitted_via_web | FS29: vjiNwcPYvtjoD8cL5yiJdz | FU29: uuid:cc7e7013-7357-40e8-a6d6-9ad41bbbb465 | FV29: 28
A30: HF core data | B30: 46128.299 | C30: 46132.542 | D30: Jhang0068 | E30: 46128 | F30: 07:15:00.000+05:00 | G30: 07:28:00.000+05:00 | H30: Tahir Mustafa | I30: Faisalabad Division | J30: Jhang | K30: Jhang | L30: 31.257982 72.306018 112.5 32.0989990234375 | M30: 31.257982 | N30: 72.306018 | O30: 112.5 | P30: 32.098999 | Q30: Urban | R30: Daewoo Express Terminal Jhang–Faisalabad Rd, Jhang | S30: Public place | T30: Transport Terminal (Bus terminal) | U30: Listed Venue | V30: 1 | W30: 0 | X30: Daewoo Express Terminal Jhang–Faisalabad Rd, Jhang | Y30: Yes( add photo evidence) | Z30: 1000075126-7_13_32.jpg | AA30: https://kf.kobotoolbox.org/api/v2/assets/a7B4UGoSq7bg72YxNv837d/data/729967768/attachments/attn3JSCpCy25LcgfFfJSQPV/ | AB30: 1 | AC30: No | AE30: No | AG30: Yes | AH30: Yes | AI30: Yes | AJ30: Does not apply / no one using tobacco or nicotine products | AK30: 0 | AL30: 0 | AM30: 0 | AN30: 0 | AO30: 0 | AP30: 0 | AQ30: 1 | AR30: 0 | AT30: Does not apply / no one using tobacco or nicotine products | AU30: No | AX30: No | BA30: No | BD30: No | BT30: Yes | FL30: 729967768 | FM30: 7907d647-6261-4a01-b052-7d1903d0edd2 | FN30: 46132.334 | FQ30: submitted_via_web | FS30: vjiNwcPYvtjoD8cL5yiJdz | FU30: uuid:7907d647-6261-4a01-b052-7d1903d0edd2 | FV30: 29
A31: HF core data | B31: 46128.302 | C31: 46132.543 | D31: Jhang0069 | E31: 46128 | F31: 07:39:00.000+05:00 | G31: 07:50:00.000+05:00 | H31: Tahir Mustafa | I31: Faisalabad Division | J31: Jhang | K31: Jhang | L31: 31.280103 72.31512 114.30000305175781 33.499000549316406 | M31: 31.280103 | N31: 72.31512 | O31: 114.3 | P31: 33.499001 | Q31: Urban | R31: Altron permium | S31: Retail outlet /Point of Sale (POS) | DC31: Fuel station | DE31: Altron permum | DF31: Farooq e Azam road | DG31: No | DH31: Not Applicable/ No Young buyers visited | DI31: No | DL31: No | DP31: No | DT31: No | DW31: No | DX31: No | EA31: No | EE31: No | EI31: No | EM31: No | EQ31: No | EU31: No | EY31: No | FC31: No | FG31: Yes | FH31: Yes | FL31: 729968050 | FM31: b4d0312d-d418-4aef-89a1-f3752929f67a | FN31: 46132.334 | FQ31: submitted_via_web | FS31: vjiNwcPYvtjoD8cL5yiJdz | FU31: uuid:b4d0312d-d418-4aef-89a1-f3752929f67a | FV31: 30
A32: HF core data | B32: 46128.336 | C32: 46132.543 | D32: Jhang 70 | E32: 46128 | F32: 08:04:00.000+05:00 | G32: 08:19:00.000+05:00 | H32: Tahir Mustafa | I32: Faisalabad Division | J32: Jhang | K32: Jhang | L32: 31.277041 72.32083 114.69999694824219 23.10099983215332 | M32: 31.277041 | N32: 72.32083 | O32: 114.7 | P32: 23.101 | Q32: Urban | R32: Gilani restaurant | S32: Public place | T32: Eatery ( Restaurant) | U32: Unlisted Venue | V32: 0 | W32: 1 | X32: Gilani restaurant | Y32: No | AC32: No | AE32: No | AG32: Yes | AH32: Yes | AI32: Yes | AJ32: Does not apply / no one using tobacco or nicotine products | AK32: 0 | AL32: 0 | AM32: 0 | AN32: 0 | AO32: 0 | AP32: 0 | AQ32: 1 | AR32: 0 | AT32: Does not apply / no one using tobacco or nicotine products | AU32: No | AX32: Yes (add photo Evidence) | AY32: 1000075127-8_7_43.jpg | AZ32: https://kf.kobotoolbox.org/api/v2/assets/a7B4UGoSq7bg72YxNv837d/data/729968199/attachments/attctcfKdGsHxxkRUiT8SdTm/ | BA32: No | BD32: Yes (add photo Evidence) | BE32: 1000075129-8_8_18.jpg | BF32: https://kf.kobotoolbox.org/api/v2/assets/a7B4UGoSq7bg72YxNv837d/data/729968199/attachments/attJYhTM6NLPyL2kZAhQpR69/ | BG32: Does not apply / no one using tobacco or nicotine products | BH32: 0 | BI32: 0 | BJ32: 0 | BK32: 0 | BL32: 0 | BM32: 0 | BN32: 1 | BO32: 0 | BQ32: No | BT32: Yes | FL32: 729968199 | FM32: 724ebff3-bdf9-478b-8c3d-852694303771 | FN32: 46132.334 | FQ32: submitted_via_web | FS32: vjiNwcPYvtjoD8cL5yiJdz | FU32: uuid:724ebff3-bdf9-478b-8c3d-852694303771 | FV32: 31
A33: HF core data | B33: 46128.353 | C33: 46132.543 | D33: Jhang0071 | E33: 46128 | F33: 08:29:00.000+05:00 | G33: 08:34:00.000+05:00 | H33: Tahir Mustafa | I33: Faisalabad Division | J33: Jhang | K33: Jhang | L33: 31.275648 72.322076 114.30000305175781 17.91900062561035 | M33: 31.275648 | N33: 72.322076 | O33: 114.3 | P33: 17.919001 | Q33: Urban | R33: Kachhari road | S33: Public Service Vehicle (PSV) | BW33: other | BX33: Raksha | BY33: Raksha | BZ33: Kachhari road | CA33: No | CB33: No | CC33: No | CD33: No | CF33: Does not apply / no one using tobacco or nicotine products | CG33: 0 | CH33: 0 | CI33: 0 | CJ33: 0 | CK33: 0 | CL33: 0 | CM33: 1 | CN33: 0 | CP33: Does not apply / no one smoking | CQ33: No | CT33: No | CW33: No | CX33: Yes | CY33: Yes | CZ33: Yes | FL33: 729968338 | FM33: cbcf5ab8-06cd-4172-ac4f-9ce1e0ce1a4e | FN33: 46132.334 | FQ33: submitted_via_web | FS33: vjiNwcPYvtjoD8cL5yiJdz | FU33: uuid:cbcf5ab8-06cd-4172-ac4f-9ce1e0ce1a4e | FV33: 32
A34: HF core data | B34: 46128.358 | C34: 46132.543 | D34: Jhang72 | E34: 46128 | F34: 08:40:00.000+05:00 | G34: 08:55:00.000+05:00 | H34: Tahir Mustafa | I34: Faisalabad Division | J34: Jhang | K34: Jhang | L34: 31.260842 72.351215 114.69999694824219 46.869998931884766 | M34: 31.260842 | N34: 72.351215 | O34: 114.7 | P34: 46.869999 | Q34: Urban | R34: Hockey stadium | S34: Public place | T34: Entertainment/sports venue - sport ground | U34: Listed Venue | V34: 1 | W34: 0 | X34: Hockey stadium | Y34: No | AC34: No | AE34: No | AG34: Yes | AH34: No | AI34: No | AJ34: Does not apply / no one using tobacco or nicotine products | AK34: 0 | AL34: 0 | AM34: 0 | AN34: 0 | AO34: 0 | AP34: 0 | AQ34: 1 | AR34: 0 | AT34: Does not apply / no one using tobacco or nicotine products | AU34: No | AX34: No | BA34: No | BD34: No | BT34: Yes | FL34: 729968499 | FM34: 9b933d40-b699-4b06-aaa5-8ab8c9aad8bb | FN34: 46132.335 | FQ34: submitted_via_web | FS34: vjiNwcPYvtjoD8cL5yiJdz | FU34: uuid:9b933d40-b699-4b06-aaa5-8ab8c9aad8bb | FV34: 33
A35: HF core data | B35: 46128.368 | C35: 46132.543 | D35: Jhang0073 | E35: 46128 | F35: 00:25:00.000+05:00 | G35: 00:39:00.000+05:00 | H35: Tahir Mustafa | I35: Faisalabad Division | J35: Jhang | K35: Jhang | L35: 31.270794 72.329522 120.637 1.6480000019073486 | M35: 31.270794 | N35: 72.329522 | O35: 120.637 | P35: 1.648 | Q35: Urban | R35: THE ROOMI EDUCATION SYSTEM JHANG opposite M | S35: Public place | T35: Educational institution - School (Private) | U35: Listed Venue | V35: 1 | W35: 0 | X35: THE ROOMI EDUCATION SYSTEM JHANG opposite M | Y35: No | AC35: No | AE35: No | AG35: Yes | AH35: Yes | AI35: Yes | AJ35: Does not apply / no one using tobacco or nicotine products | AK35: 0 | AL35: 0 | AM35: 0 | AN35: 0 | AO35: 0 | AP35: 0 | AQ35: 1 | AR35: 0 | AT35: Does not apply / no one using tobacco or nicotine products | AU35: No | AX35: Yes (add photo Evidence) | AY35: 1000075234-12_28_12.jpg | AZ35: https://kf.kobotoolbox.org/api/v2/assets/a7B4UGoSq7bg72YxNv837d/data/729968642/attachments/attUnfvLyjXBaYPNctTGiqqc/ | BA35: No | BD35: No | BT35: Yes | FL35: 729968642 | FM35: b2cb1100-7f9d-4887-8900-b25dacca2701 | FN35: 46132.335 | FQ35: submitted_via_web | FS35: vjiNwcPYvtjoD8cL5yiJdz | FU35: uuid:b2cb1100-7f9d-4887-8900-b25dacca2701 | FV35: 34
A36: HF core data | B36: 46128.395 | C36: 46132.543 | D36: Jhang0074 | E36: 46128 | F36: 13:00:00.000+05:00 | G36: 01:15:00.000+05:00 | H36: Tahir Mustafa | I36: Faisalabad Division | J36: Jhang | K36: Jhang | L36: 31.26616 72.322457 131.659 15 | M36: 31.26616 | N36: 72.322457 | O36: 131.659 | P36: 15 | Q36: Urban | R36: Beaconhouse school system jhang camp | S36: Public place | T36: Educational institution - School (Private) | U36: Unlisted Venue | V36: 0 | W36: 1 | X36: Beaconhouse school system jhang camp | Y36: No | AC36: No | AE36: No | AG36: Yes | AH36: Yes | AI36: Yes | AJ36: Does not apply / no one using tobacco or nicotine products | AK36: 0 | AL36: 0 | AM36: 0 | AN36: 0 | AO36: 0 | AP36: 0 | AQ36: 1 | AR36: 0 | AT36: Does not apply / no one using tobacco or nicotine products | AU36: No | AX36: No | BA36: No | BD36: No | BT36: Yes | BV36: 6 THE INNOVATIVE HOUSE (BOYS) HIGH SCHOOL Block No 7 Jhang City map is not correct provide so unlisted give | FL36: 729968859 | FM36: 6ed01fac-36e8-46a2-9f7d-e0f624c27c94 | FN36: 46132.335 | FQ36: submitted_via_web | FS36: vjiNwcPYvtjoD8cL5yiJdz | FU36: uuid:6ed01fac-36e8-46a2-9f7d-e0f624c27c94 | FV36: 35
